Workbook

Sheet TOPSHEET
A1: JAKKS Pacific LOGO | B1: Ralph LOGO | C1: Disney Darlings EU3 Launch Campaign Budget Estimate 2026
C2: Phases | F2: Budget Tiers 700 /. 1 / 1.5
A3: Function | B3: Details | C3: Pre-Launch Planning & Production | D3: Wave 1: Smyths Launch | E3: Wave 2: Holiday 2026 | F3: TOTAL COST USD$ (BRONZE) | G3: TOTAL COST USD$ (SILVER) | H3: TOTAL COST USD$ (GOLD)
C4: Feb - Apr | D4: May - Aug | E4: Sept - Dec
A5: CREATIVE & STRATEGY | B5: Creative and strategic direction, concept, scripting, strategy planning | C5: ='CREATIVE & STRATEGY'!D53 -> 30800 | D5: ='CREATIVE & STRATEGY'!F53 -> 20560 | E5: ='CREATIVE & STRATEGY'!H53 -> 20560 | F5: =SUM(C5:E5) -> 71920 | G5: =F5 -> 71920 | H5: =F5 -> 71920
A6: CREATIVE PRODUCTION | B6: Video production (shoot inc location, crew, talent), post-production (design, GFX, editing, finishing) supply/trafficking of video and static assets for advertisng, organic and POS | C6: ='CREATIVE PRODUCTION'!D53 -> 228016 | D6: ='CREATIVE PRODUCTION'!F53 -> 26560 | E6: ='CREATIVE PRODUCTION'!H53 -> 26560 | F6: =SUM(C6:E6) -> 281136 | G6: =F6 -> 281136 | H6: =F6 -> 281136
A7: MEDIA PLANNING & BUYING | B7: Communication channel / media planning and buying across TV/CTV, YouTube, Social, POS and OOH. Creator discovery, partnerships, contracts and management | C7: ='MEDIA PLANNING'!D54 -> 16920 | D7: ='MEDIA PLANNING'!F54+'MEDIA BUYING'!H12 -> 104640 | E7: ='MEDIA PLANNING'!H54+'MEDIA BUYING'!H13 -> 258760 | F7: =SUM(C7:E7) -> 380320 | G7: ='MEDIA PLANNING'!D55+'MEDIA PLANNING'!F55+'MEDIA PLANNING'!H55+'MEDIA BUYING'!Q2 -> 597820 | H7: ='MEDIA PLANNING'!D56+'MEDIA PLANNING'!F56+'MEDIA PLANNING'!H56+'MEDIA BUYING'!W2 -> 1135320
A8: RESEARCH & REPORTING | B8: Research, brand tracking and insight direction, campaign management and reactive planning | C8: ='RESEARCH & REPORTING'!D56 -> 61620 | D8: ='RESEARCH & REPORTING'!F56 -> 23920 | E8: ='RESEARCH & REPORTING'!H56 -> 23920 | F8: =SUM(C8:E8) -> 109460 | G8: =F8 -> 109460 | H8: =F8 -> 109460
A10: COST USD$ | C10: =SUM(C5:C8) -> 337356 | D10: =SUM(D5:D8) -> 175680 | E10: =SUM(E5:E8) -> 329800 | F10: =SUM(F4:F8) -> 842836 | G10: =SUM(G4:G8) -> 1060336 | H10: =SUM(H4:H8) -> 1597836
A11: EST IMPRESSIONS | F11: ='MEDIA BUYING'!I11 -> 61203704 | G11: ='MEDIA BUYING'!O11 -> 1.0200617e+08 | H11: ='MEDIA BUYING'!U11 -> 1.6422054e+08
A12: NOTES
E14: INTERNAL NOTES
E15: Fee for Ralph | F15: ='CREATIVE & STRATEGY'!B55+'CREATIVE PRODUCTION'!B55+'MEDIA PLANNING'!J54+'RESEARCH & REPORTING'!B58 -> 320336
E16: Per month | F16: =F15/11 -> 29121.455
E18: Media costs | F18: Could reduce in line with total cost to meet tiered budgets
E19: Creative Prod | F19: Placeholder for shoot
F20: Doesnt change dependent on tier / media spend | G20: Should at least inc costs for telly for trafficking

Sheet CREATIVE & STRATEGY
A1: RALPH RATECARD | B1: USD $ | C1: PRE-LAUNCH - FEB-APR | E1: SMYTHS - MAY-AUG | G1: HOLIDAYS - SEPT-DEC
B2: per hour | C2: No of Hours | D2: Total | E2: No of Hours | F2: Total | G2: No of Hours | H2: Total
A3: Planning / Concepting
A4: Executive Creative Director | B4: 450 | D4: =B4*C4 -> 0 | F4: =B4*E4 -> 0 | H4: =B4*G4 -> 0
A5: Creative Director | B5: 350 | C5: 40 | D5: =B5*C5 -> 14000 | E5: 16 | F5: =B5*E5 -> 5600 | G5: 16 | H5: =B5*G5 -> 5600
A6: Head of Creative | B6: 250 | C6: 24 | D6: =B6*C6 -> 6000 | E6: 16 | F6: =B6*E6 -> 4000 | G6: 16 | H6: =B6*G6 -> 4000
A7: Creative | B7: 200 | D7: =B7*C7 -> 0 | F7: =B7*E7 -> 0 | H7: =B7*G7 -> 0
A8: Planner | B8: 200 | C8: 8 | D8: =B8*C8 -> 1600 | E8: 16 | F8: =B8*E8 -> 3200 | G8: 16 | H8: =B8*G8 -> 3200
A9: Data Insights / Analytics | B9: 200 | D9: =B9*C9 -> 0 | F9: =B9*E9 -> 0 | H9: =B9*G9 -> 0
H10: =B10*G10 -> 0
A11: Art Direction / Design | H11: =B11*G11 -> 0
A12: Art Director | B12: 250 | D12: =B12*C12 -> 0 | F12: =B12*E12 -> 0 | H12: =B12*G12 -> 0
A13: Senior Designer | B13: 180 | D13: =B13*C13 -> 0 | F13: =B13*E13 -> 0 | H13: =B13*G13 -> 0
A14: Designer | B14: 150 | D14: =B14*C14 -> 0 | F14: =B14*E14 -> 0 | H14: =B14*G14 -> 0
A15: Junior Designer | B15: 120 | D15: =B15*C15 -> 0 | F15: =B15*E15 -> 0 | H15: =B15*G15 -> 0
H16: =B16*G16 -> 0
A17: Development | H17: =B17*G17 -> 0
A18: Frontend Developer | B18: 200 | D18: =B18*C18 -> 0 | F18: =B18*E18 -> 0 | H18: =B18*G18 -> 0
A19: Backend/Database Developer | B19: 200 | D19: =B19*C19 -> 0 | F19: =B19*E19 -> 0 | H19: =B19*G19 -> 0
A20: Tester | B20: 100 | D20: =B20*C20 -> 0 | F20: =B20*E20 -> 0 | H20: =B20*G20 -> 0
H21: =B21*G21 -> 0
A22: Video Production | H22: =B22*G22 -> 0
A23: Director | B23: 350 | D23: =B23*C23 -> 0 | F23: =B23*E23 -> 0 | H23: =B23*G23 -> 0
A24: Sr Video Producer | B24: 225 | D24: =B24*C24 -> 0 | F24: =B24*E24 -> 0 | H24: =B24*G24 -> 0
A25: Senior Video Editor | B25: 180 | D25: =B25*C25 -> 0 | F25: =B25*E25 -> 0 | H25: =B25*G25 -> 0
A26: Video Editor | B26: 150 | D26: =B26*C26 -> 0 | F26: =B26*E26 -> 0 | H26: =B26*G26 -> 0
A27: Motion Graphics / Animation | B27: 180 | D27: =B27*C27 -> 0 | F27: =B27*E27 -> 0 | H27: =B27*G27 -> 0
A28: 3d Modelling and Animation | B28: 200 | D28: =B28*C28 -> 0 | F28: =B28*E28 -> 0 | H28: =B28*G28 -> 0
H29: =B29*G29 -> 0
A30: Sound Editing | H30: =B30*G30 -> 0
A31: Sound Engineer | B31: 250 | D31: =B31*C31 -> 0 | F31: =B31*E31 -> 0 | H31: =B31*G31 -> 0
A32: Sound Assistant | B32: 180 | D32: =B32*C32 -> 0 | F32: =B32*E32 -> 0 | H32: =B32*G32 -> 0
H33: =B33*G33 -> 0
A34: Social | H34: =B34*G34 -> 0
A35: Head of Social | B35: 250 | D35: =B35*C35 -> 0 | F35: =B35*E35 -> 0 | H35: =B35*G35 -> 0
A36: Social Lead | B36: 200 | D36: =B36*C36 -> 0 | F36: =B36*E36 -> 0 | H36: =B36*G36 -> 0
A37: Senior Social Strategist | B37: 180 | C37: 16 | D37: =B37*C37 -> 2880 | E37: 16 | F37: =B37*E37 -> 2880 | G37: 16 | H37: =B37*G37 -> 2880
A38: Social Strategist | B38: 150 | D38: =B38*C38 -> 0 | F38: =B38*E38 -> 0 | H38: =B38*G38 -> 0
A39: Social Coordinator/Strategy Exec | B39: 120 | D39: =B39*C39 -> 0 | F39: =B39*E39 -> 0 | H39: =B39*G39 -> 0
H40: =B40*G40 -> 0
...

Sheet CREATIVE PRODUCTION
A1: RALPH RATECARD | B1: USD $ | C1: PRE-LAUNCH - FEB-APR | E1: SMYTHS - MAY-AUG | G1: HOLIDAYS - SEPT-DEC
B2: per hour | C2: No of Hours | D2: Total | E2: No of Hours | F2: Total | G2: No of Hours | H2: Total
A3: Planning / Concepting
A4: Executive Creative Director | B4: 450 | D4: =B4*C4 -> 0 | F4: =B4*E4 -> 0 | H4: =B4*G4 -> 0
A5: Creative Director | B5: 350 | C5: 40 | D5: =B5*C5 -> 14000 | E5: 16 | F5: =B5*E5 -> 5600 | G5: 16 | H5: =B5*G5 -> 5600
A6: Head of Creative | B6: 250 | C6: 24 | D6: =B6*C6 -> 6000 | E6: 16 | F6: =B6*E6 -> 4000 | G6: 16 | H6: =B6*G6 -> 4000
A7: Creative | B7: 200 | D7: =B7*C7 -> 0 | F7: =B7*E7 -> 0 | H7: =B7*G7 -> 0
A8: Planner | B8: 200 | C8: 8 | D8: =B8*C8 -> 1600 | F8: =B8*E8 -> 0 | H8: =B8*G8 -> 0
A9: Data Insights / Analytics | B9: 200 | D9: =B9*C9 -> 0 | F9: =B9*E9 -> 0 | H9: =B9*G9 -> 0
H10: =B10*G10 -> 0
A11: Art Direction / Design | H11: =B11*G11 -> 0
A12: Art Director | B12: 250 | C12: 12 | D12: =B12*C12 -> 3000 | F12: =B12*E12 -> 0 | H12: =B12*G12 -> 0
A13: Senior Designer | B13: 180 | C13: 12 | D13: =B13*C13 -> 2160 | F13: =B13*E13 -> 0 | H13: =B13*G13 -> 0
A14: Designer | B14: 150 | D14: =B14*C14 -> 0 | F14: =B14*E14 -> 0 | H14: =B14*G14 -> 0
A15: Junior Designer | B15: 120 | D15: =B15*C15 -> 0 | F15: =B15*E15 -> 0 | H15: =B15*G15 -> 0
H16: =B16*G16 -> 0
A17: Development | H17: =B17*G17 -> 0
A18: Frontend Developer | B18: 200 | D18: =B18*C18 -> 0 | F18: =B18*E18 -> 0 | H18: =B18*G18 -> 0
A19: Backend/Database Developer | B19: 200 | D19: =B19*C19 -> 0 | F19: =B19*E19 -> 0 | H19: =B19*G19 -> 0
A20: Tester | B20: 100 | D20: =B20*C20 -> 0 | F20: =B20*E20 -> 0 | H20: =B20*G20 -> 0
H21: =B21*G21 -> 0
A22: Video Production | H22: =B22*G22 -> 0
A23: Director | B23: 350 | D23: =B23*C23 -> 0 | F23: =B23*E23 -> 0 | H23: =B23*G23 -> 0
A24: Sr Video Producer | B24: 225 | D24: =B24*C24 -> 0 | F24: =B24*E24 -> 0 | H24: =B24*G24 -> 0
A25: Senior Video Editor | B25: 180 | C25: 40 | D25: =B25*C25 -> 7200 | F25: =B25*E25 -> 0 | H25: =B25*G25 -> 0
A26: Video Editor | B26: 150 | C26: 80 | D26: =B26*C26 -> 12000 | F26: =B26*E26 -> 0 | H26: =B26*G26 -> 0
A27: Motion Graphics / Animation | B27: 180 | C27: 32 | D27: =B27*C27 -> 5760 | F27: =B27*E27 -> 0 | H27: =B27*G27 -> 0
A28: 3d Modelling and Animation | B28: 200 | D28: =B28*C28 -> 0 | F28: =B28*E28 -> 0 | H28: =B28*G28 -> 0
H29: =B29*G29 -> 0
A30: Sound Editing | H30: =B30*G30 -> 0
A31: Sound Engineer | B31: 250 | D31: =B31*C31 -> 0 | F31: =B31*E31 -> 0 | H31: =B31*G31 -> 0
A32: Sound Assistant | B32: 180 | D32: =B32*C32 -> 0 | F32: =B32*E32 -> 0 | H32: =B32*G32 -> 0
H33: =B33*G33 -> 0
A34: Social | H34: =B34*G34 -> 0
A35: Head of Social | B35: 250 | D35: =B35*C35 -> 0 | F35: =B35*E35 -> 0 | H35: =B35*G35 -> 0
A36: Social Lead | B36: 200 | C36: 16 | D36: =B36*C36 -> 3200 | E36: 16 | F36: =B36*E36 -> 3200 | G36: 16 | H36: =B36*G36 -> 3200
A37: Senior Social Strategist | B37: 180 | D37: =B37*C37 -> 0 | F37: =B37*E37 -> 0 | H37: =B37*G37 -> 0
A38: Social Strategist | B38: 150 | C38: 16 | D38: =B38*C38 -> 2400 | F38: =B38*E38 -> 0 | H38: =B38*G38 -> 0
A39: Social Coordinator/Strategy Exec | B39: 120 | D39: =B39*C39 -> 0 | F39: =B39*E39 -> 0 | H39: =B39*G39 -> 0
H40: =B40*G40 -> 0
...

Sheet MEDIA PLANNING
A1: RALPH RATECARD | B1: USD $ | C1: PRE-LAUNCH - FEB-APR | E1: SMYTHS - MAY-AUG | G1: HOLIDAYS - SEPT-DEC
B2: per hour | C2: No of Hours | D2: Total | E2: No of Hours | F2: Total | G2: No of Hours | H2: Total
A3: Planning / Concepting
A4: Executive Creative Director | B4: 450 | D4: =B4*C4 -> 0 | F4: =B4*E4 -> 0 | H4: =B4*G4 -> 0
A5: Creative Director | B5: 350 | D5: =B5*C5 -> 0 | F5: =B5*E5 -> 0 | H5: =B5*G5 -> 0
A6: Head of Creative | B6: 250 | D6: =B6*C6 -> 0 | F6: =B6*E6 -> 0 | H6: =B6*G6 -> 0
A7: Creative | B7: 200 | D7: =B7*C7 -> 0 | F7: =B7*E7 -> 0 | H7: =B7*G7 -> 0
A8: Planner | B8: 200 | C8: 8 | D8: =B8*C8 -> 1600 | E8: 12 | F8: =B8*E8 -> 2400 | G8: 16 | H8: =B8*G8 -> 3200
A9: Data Insights / Analytics | B9: 200 | C9: 8 | D9: =B9*C9 -> 1600 | E9: 12 | F9: =B9*E9 -> 2400 | G9: 16 | H9: =B9*G9 -> 3200
H10: =B10*G10 -> 0
A11: Art Direction / Design | H11: =B11*G11 -> 0
A12: Art Director | B12: 250 | D12: =B12*C12 -> 0 | F12: =B12*E12 -> 0 | H12: =B12*G12 -> 0
A13: Senior Designer | B13: 180 | D13: =B13*C13 -> 0 | F13: =B13*E13 -> 0 | H13: =B13*G13 -> 0
A14: Designer | B14: 150 | D14: =B14*C14 -> 0 | F14: =B14*E14 -> 0 | H14: =B14*G14 -> 0
A15: Junior Designer | B15: 120 | D15: =B15*C15 -> 0 | F15: =B15*E15 -> 0 | H15: =B15*G15 -> 0
H16: =B16*G16 -> 0
A17: Development | H17: =B17*G17 -> 0
A18: Frontend Developer | B18: 200 | D18: =B18*C18 -> 0 | F18: =B18*E18 -> 0 | H18: =B18*G18 -> 0
A19: Backend/Database Developer | B19: 200 | D19: =B19*C19 -> 0 | F19: =B19*E19 -> 0 | H19: =B19*G19 -> 0
A20: Tester | B20: 100 | D20: =B20*C20 -> 0 | F20: =B20*E20 -> 0 | H20: =B20*G20 -> 0
H21: =B21*G21 -> 0
A22: Video Production | H22: =B22*G22 -> 0
A23: Director | B23: 350 | D23: =B23*C23 -> 0 | F23: =B23*E23 -> 0 | H23: =B23*G23 -> 0
A24: Sr Video Producer | B24: 225 | D24: =B24*C24 -> 0 | F24: =B24*E24 -> 0 | H24: =B24*G24 -> 0
A25: Senior Video Editor | B25: 180 | D25: =B25*C25 -> 0 | F25: =B25*E25 -> 0 | H25: =B25*G25 -> 0
A26: Video Editor | B26: 150 | D26: =B26*C26 -> 0 | F26: =B26*E26 -> 0 | H26: =B26*G26 -> 0
A27: Motion Graphics / Animation | B27: 180 | D27: =B27*C27 -> 0 | F27: =B27*E27 -> 0 | H27: =B27*G27 -> 0
A28: 3d Modelling and Animation | B28: 200 | D28: =B28*C28 -> 0 | F28: =B28*E28 -> 0 | H28: =B28*G28 -> 0
H29: =B29*G29 -> 0
A30: Sound Editing | H30: =B30*G30 -> 0
A31: Sound Engineer | B31: 250 | D31: =B31*C31 -> 0 | F31: =B31*E31 -> 0 | H31: =B31*G31 -> 0
A32: Sound Assistant | B32: 180 | D32: =B32*C32 -> 0 | F32: =B32*E32 -> 0 | H32: =B32*G32 -> 0
H33: =B33*G33 -> 0
A34: Social | H34: =B34*G34 -> 0
A35: Head of Social | B35: 250 | D35: =B35*C35 -> 0 | F35: =B35*E35 -> 0 | H35: =B35*G35 -> 0
A36: Social Lead | B36: 200 | C36: 2 | D36: =B36*C36 -> 400 | F36: =B36*E36 -> 0 | H36: =B36*G36 -> 0
A37: Senior Social Strategist | B37: 180 | D37: =B37*C37 -> 0 | F37: =B37*E37 -> 0 | H37: =B37*G37 -> 0
A38: Social Strategist | B38: 150 | D38: =B38*C38 -> 0 | F38: =B38*E38 -> 0 | H38: =B38*G38 -> 0
A39: Social Coordinator/Strategy Exec | B39: 120 | D39: =B39*C39 -> 0 | F39: =B39*E39 -> 0 | H39: =B39*G39 -> 0
H40: =B40*G40 -> 0
...

Sheet MEDIA BUYING
A1: MEDIA CHANNEL | B1: Targeting | C1: Spend Split (BRONZE) % | D1: CPM £ Broad | E1: CPM £ Targeted | F1: CPM $ Broad | G1: CPM $ Targeted | H1: SPEND (BRONZE) | I1: IMPRESSIONS BROAD | J1: IMPRESSIONS TGTED | K1: BUDGET TOTAL | M1: SPLIT | N1: SPEND (SILVER) | O1: IMP BROAD | P1: IMP TGTD | Q1: BUDGET TOTAL | S1: SPLIT | T1: SPEND (GOLD) | U1: IMP BROAD | V1: IMP TGTD | W1: BUDGET TOTAL
A2: TV | C2: 0 | E2: 115 | G2: =E2*1.35 -> 155.25 | H2: =K$2*C2 -> 0 | I2: =(H2/G2)*1000 -> 0 | J2: =(H2/G2)*1000 -> 0 | K2: 300000 | N2: =Q$2*C2 -> 0 | O2: =(N2/G2)*1000 -> 0 | P2: =(N2/G2)*1000 -> 0 | Q2: 500000 | S2: 0.25 | T2: =W$2*S2 -> 250000 | U2: =(T2/G2)*1000 -> 1610306 | V2: =(T2/G2)*1000 -> 1610306 | W2: 1000000
A3: CTV | C3: 0.175 | E3: 35 | G3: =E3*1.35 -> 47.25 | H3: =K$2*C3 -> 52500 | I3: =(H3/G3)*1000 -> 1111111.1 | J3: =(H3/G3)*1000 -> 1111111.1 | N3: =Q$2*C3 -> 87500 | O3: =(N3/G3)*1000 -> 1851851.9 | P3: =(N3/G3)*1000 -> 1851851.9 | S3: 0.1 | T3: =W$2*S3 -> 100000 | U3: =(T3/G3)*1000 -> 2116402.1 | V3: =(T3/G3)*1000 -> 2116402.1
A4: YOUTUBE | C4: 0.15 | D4: 3 | E4: 8.5 | F4: =D4*1.35 -> 4.05 | G4: =E4*1.35 -> 11.475 | H4: =K$2*C4 -> 45000 | I4: =(H4/F4)*1000 -> 11111111 | J4: =(H4/G4)*1000 -> 3921568.6 | N4: =Q$2*C4 -> 75000 | O4: =(N4/F4)*1000 -> 18518519 | P4: =(N4/G4)*1000 -> 6535947.7 | S4: 0.1 | T4: =W$2*S4 -> 100000 | U4: =(T4/F4)*1000 -> 24691358 | V4: =(T4/G4)*1000 -> 8714596.9
A5: META | C5: 0.15 | D5: 1.5 | E5: 5 | F5: =D5*1.35 -> 2.025 | G5: =E5*1.35 -> 6.75 | H5: =K$2*C5 -> 45000 | I5: =(H5/F5)*1000 -> 22222222 | J5: =(H5/G5)*1000 -> 6666666.7 | N5: =Q$2*C5 -> 75000 | O5: =(N5/F5)*1000 -> 37037037 | P5: =(N5/G5)*1000 -> 11111111 | S5: 0.1 | T5: =W$2*S5 -> 100000 | U5: =(T5/F5)*1000 -> 49382716 | V5: =(T5/G5)*1000 -> 14814815
A6: TIKTOK | C6: 0.1 | D6: 1.5 | E6: 5 | F6: =D6*1.35 -> 2.025 | G6: =E6*1.35 -> 6.75 | H6: =K$2*C6 -> 30000 | I6: =(H6/F6)*1000 -> 14814815 | J6: =(H6/G6)*1000 -> 4444444.4 | N6: =Q$2*C6 -> 50000 | O6: =(N6/F6)*1000 -> 24691358 | P6: =(N6/G6)*1000 -> 7407407.4 | S6: 0.1 | T6: =W$2*S6 -> 100000 | U6: =(T6/F6)*1000 -> 49382716 | V6: =(T6/G6)*1000 -> 14814815
A7: OOH/DOOH | C7: 0.2 | D7: 10 | E7: 12.5 | F7: =D7*1.35 -> 13.5 | G7: =E7*1.35 -> 16.875 | H7: =K$2*C7 -> 60000 | I7: =(H7/F7)*1000 -> 4444444.4 | J7: =(H7/G7)*1000 -> 3555555.6 | N7: =Q$2*C7 -> 100000 | O7: =(N7/F7)*1000 -> 7407407.4 | P7: =(N7/G7)*1000 -> 5925925.9 | S7: 0.15 | T7: =W$2*S7 -> 150000 | U7: =(T7/F7)*1000 -> 11111111 | V7: =(T7/G7)*1000 -> 8888888.9
A8: CREATORS | C8: 0.15 | D8: 10 | E8: 30 | F8: =D8*1.35 -> 13.5 | G8: =E8*1.35 -> 40.5 | H8: =K$2*C8 -> 45000 | I8: =(H8/F8)*1000 -> 3333333.3 | J8: =(H8/G8)*1000 -> 1111111.1 | N8: =Q$2*C8 -> 75000 | O8: =(N8/F8)*1000 -> 5555555.6 | P8: =(N8/G8)*1000 -> 1851851.9 | S8: 0.1 | T8: =W$2*S8 -> 100000 | U8: =(T8/F8)*1000 -> 7407407.4 | V8: =(T8/G8)*1000 -> 2469135.8
A9: RETAIL DSP (AMZN) | C9: 0.075 | D9: 4 | E9: 5 | F9: =D9*1.35 -> 5.4 | G9: =E9*1.35 -> 6.75 | H9: =K$2*C9 -> 22500 | I9: =(H9/F9)*1000 -> 4166666.7 | J9: =(H9/G9)*1000 -> 3333333.3 | N9: =Q$2*C9 -> 37500 | O9: =(N9/F9)*1000 -> 6944444.4 | P9: =(N9/G9)*1000 -> 5555555.6 | S9: 0.1 | T9: =W$2*S9 -> 100000 | U9: =(T9/F9)*1000 -> 18518519 | V9: =(T9/G9)*1000 -> 14814815
K10: AVE CPM BROAD | L10: AVE CPM TGTED | Q10: AVE CPM BROAD | R10: AVE TGTED | W10: AVE CPM BROAD | X10: AVE CPM TGTED
A11: TOTAL / AVE | C11: =SUM(C2:C9) -> 1 | H11: =K$2*C11 -> 300000 | I11: =SUM(I2:I9) -> 61203704 | J11: =sum(J2:J9) -> 24143791 | K11: =(H11/I11)*1000 -> 4.9016641 | L11: =(H11/J11)*1000 -> 12.425555 | N11: =Q$2*C11 -> 500000 | O11: =SUM(O2:O9) -> 1.0200617e+08 | P11: =sum(P2:P9) -> 40239651 | Q11: =(N11/O11)*1000 -> 4.9016641 | R11: =(N11/P11)*1000 -> 12.425555 | S11: =sum(S2:S9) -> 1 | T11: =W$2*S11 -> 1000000 | U11: =SUM(U2:U9) -> 1.6422054e+08 | V11: =SUM(V2:V9) -> 68243774 | W11: =(T11/U11)*1000 -> 6.0893724 | X11: =(T11/V11)*1000 -> 14.653351
A12: SMYTHS | C12: 0.25 | H12: =K$2*C12 -> 75000 | I12: =I11*C12 -> 15300926 | J12: =J11*C12 -> 6035947.7 | M12: 0.25 | N12: =N11*C12 -> 125000 | O12: =O11*C12 -> 25501543 | P12: =P11*C12 -> 10059913 | S12: 0.2 | T12: =W$2*S12 -> 200000 | U12: =U11*S12 -> 32844107 | V12: =V11*S12 -> 13648755
A13: HOLIDAY | C13: 0.75 | H13: =K$2*C13 -> 225000 | I13: =I11*0.75 -> 45902778 | J13: =J11*0.75 -> 18107843 | M13: 0.75 | N13: =N11*C13 -> 375000 | O13: =O11*0.75 -> 76504630 | P13: =P11*0.75 -> 30179739 | S13: 0.8 | T13: =W$2*S13 -> 800000 | U13: =U11*S13 -> 1.3137643e+08 | V13: =V11*S13 -> 54595019
A15: NOTES & ROUGH CHANNEL SPLITS FOR PRESENTATION

Sheet RESEARCH & REPORTING
A1: RALPH RATECARD | B1: USD $ | C1: PRE-LAUNCH - FEB-APR | E1: SMYTHS - MAY-AUG | G1: HOLIDAYS - SEPT-DEC
B2: per hour | C2: No of Hours | D2: Total | E2: No of Hours | F2: Total | G2: No of Hours | H2: Total
A3: Planning / Concepting
A4: Executive Creative Director | B4: 450 | D4: =B4*C4 -> 0 | F4: =B4*E4 -> 0 | H4: =B4*G4 -> 0
A5: Creative Director | B5: 350 | D5: =B5*C5 -> 0 | F5: =B5*E5 -> 0 | H5: =B5*G5 -> 0
A6: Head of Creative | B6: 250 | D6: =B6*C6 -> 0 | F6: =B6*E6 -> 0 | H6: =B6*G6 -> 0
A7: Creative | B7: 200 | D7: =B7*C7 -> 0 | F7: =B7*E7 -> 0 | H7: =B7*G7 -> 0
A8: Planner | B8: 200 | D8: =B8*C8 -> 0 | F8: =B8*E8 -> 0 | H8: =B8*G8 -> 0
A9: Data Insights / Analytics | B9: 200 | C9: 8 | D9: =B9*C9 -> 1600 | E9: 32 | F9: =B9*E9 -> 6400 | G9: 32 | H9: =B9*G9 -> 6400
H10: =B10*G10 -> 0
A11: Art Direction / Design | H11: =B11*G11 -> 0
A12: Art Director | B12: 250 | D12: =B12*C12 -> 0 | F12: =B12*E12 -> 0 | H12: =B12*G12 -> 0
A13: Senior Designer | B13: 180 | D13: =B13*C13 -> 0 | F13: =B13*E13 -> 0 | H13: =B13*G13 -> 0
A14: Designer | B14: 150 | D14: =B14*C14 -> 0 | F14: =B14*E14 -> 0 | H14: =B14*G14 -> 0
A15: Junior Designer | B15: 120 | D15: =B15*C15 -> 0 | F15: =B15*E15 -> 0 | H15: =B15*G15 -> 0
H16: =B16*G16 -> 0
A17: Development | H17: =B17*G17 -> 0
A18: Frontend Developer | B18: 200 | D18: =B18*C18 -> 0 | F18: =B18*E18 -> 0 | H18: =B18*G18 -> 0
A19: Backend/Database Developer | B19: 200 | D19: =B19*C19 -> 0 | F19: =B19*E19 -> 0 | H19: =B19*G19 -> 0
A20: Tester | B20: 100 | D20: =B20*C20 -> 0 | F20: =B20*E20 -> 0 | H20: =B20*G20 -> 0
H21: =B21*G21 -> 0
A22: Video Production | H22: =B22*G22 -> 0
A23: Director | B23: 350 | D23: =B23*C23 -> 0 | F23: =B23*E23 -> 0 | H23: =B23*G23 -> 0
A24: Sr Video Producer | B24: 225 | D24: =B24*C24 -> 0 | F24: =B24*E24 -> 0 | H24: =B24*G24 -> 0
A25: Senior Video Editor | B25: 180 | D25: =B25*C25 -> 0 | F25: =B25*E25 -> 0 | H25: =B25*G25 -> 0
A26: Video Editor | B26: 150 | D26: =B26*C26 -> 0 | F26: =B26*E26 -> 0 | H26: =B26*G26 -> 0
A27: Motion Graphics / Animation | B27: 180 | D27: =B27*C27 -> 0 | F27: =B27*E27 -> 0 | H27: =B27*G27 -> 0
A28: 3d Modelling and Animation | B28: 200 | D28: =B28*C28 -> 0 | F28: =B28*E28 -> 0 | H28: =B28*G28 -> 0
H29: =B29*G29 -> 0
A30: Sound Editing | H30: =B30*G30 -> 0
A31: Sound Engineer | B31: 250 | D31: =B31*C31 -> 0 | F31: =B31*E31 -> 0 | H31: =B31*G31 -> 0
A32: Sound Assistant | B32: 180 | D32: =B32*C32 -> 0 | F32: =B32*E32 -> 0 | H32: =B32*G32 -> 0
H33: =B33*G33 -> 0
A34: Social | H34: =B34*G34 -> 0
A35: Head of Social | B35: 250 | D35: =B35*C35 -> 0 | F35: =B35*E35 -> 0 | H35: =B35*G35 -> 0
A36: Social Lead | B36: 200 | D36: =B36*C36 -> 0 | F36: =B36*E36 -> 0 | H36: =B36*G36 -> 0
A37: Senior Social Strategist | B37: 180 | D37: =B37*C37 -> 0 | F37: =B37*E37 -> 0 | H37: =B37*G37 -> 0
A38: Social Strategist | B38: 150 | D38: =B38*C38 -> 0 | F38: =B38*E38 -> 0 | H38: =B38*G38 -> 0
A39: Social Coordinator/Strategy Exec | B39: 120 | D39: =B39*C39 -> 0 | F39: =B39*E39 -> 0 | H39: =B39*G39 -> 0
H40: =B40*G40 -> 0
...
